<?xml version="1.0" ?>
<!-- =================================================================================== -->
<!-- |    This document was autogenerated by xacro from ../../../../ros2/src/shared/march_description/urdf/march4.xacro | -->
<!-- |    EDITING THIS FILE BY HAND IS NOT RECOMMENDED                                 | -->
<!-- =================================================================================== -->
<!-- Revolute-Revolute Manipulator -->
<robot name="march">
  <!-- Square dimensions (widthxwidth) of beams -->
  <!-- mass = Hip base + HAA actuators -->
  <!-- mass = Moving hip -->
  <!-- mass = KFE joint + HFE joint + Upper leg -->
  <!-- mass = Ankle actuator + Lower leg -->
  <!-- mass = Passive ankle + foot -->
  <!-- rad -->
  <!-- rad -->
  <!-- rad/s -->
  <!-- rad -->
  <!-- rad -->
  <!-- rad/s -->
  <!-- Space btw top of beam and the each joint -->
  <gazebo>
    <plugin filename="libgazebo_ros_control.so" name="gazebo_ros_control">
      <robotNamespace>/march</robotNamespace>
      <robotSimType>gazebo_ros_control/DefaultRobotHWSim</robotSimType>
    </plugin>
  </gazebo>
  <material name="blue">
    <color rgba="0 0 0.6 1"/>
  </material>
  <!-- Used for fixing robot to Gazebo 'base_link' -->
  <link name="world"/>
  <!-- Parts -->
  <!-- Hip-->
  <link name="hip_base">
    <visual>
      <origin rpy="0 0 3.141592653589793" xyz="-0.1395 0 0"/>
      <geometry>
        <mesh filename="package://march_description/urdf/stl-files/HipBase.stl" scale="1 1 1"/>
      </geometry>
      <material name="blue"/>
    </visual>
    <inertial>
      <origin rpy="0 0 0" xyz="0.008488999999999997 0.016341 0.147761"/>
      <mass value="8.686"/>
      <inertia ixx="0.141" ixy="3.36e-05" ixz="-0.007" iyy="0.087" iyz="0.0005089" izz="0.091"/>
    </inertial>
    <collision>
      <origin rpy="0 0 0" xyz="0 0 0"/>
      <geometry>
        <box size="0.05 0.16 0.05"/>
      </geometry>
    </collision>
  </link>
  <!-- IMU-->
  <link name="imu_link">
    </link>
  <!-- Left Moving Hip-->
  <link name="hip_aa_frame_left_side">
    <visual>
      <origin rpy="0 0 3.141592653589793" xyz="-0.1395 0.08 0"/>
      <geometry>
        <mesh filename="package://march_description/urdf/stl-files/LeftHAA.stl" scale="1 1 1"/>
      </geometry>
      <material name="blue"/>
    </visual>
    <collision>
      <origin rpy="0 0 0" xyz="0 -0.085 0"/>
      <geometry>
        <box size="0.05 0.17 0.05"/>
      </geometry>
    </collision>
  </link>
  <link name="hip_aa_frame_left_front">
    <inertial>
      <origin rpy="0 0 0" xyz="-0.03140600000000002 0.05224200000000001 0.029507"/>
      <mass value="2.982"/>
      <inertia ixx="0.013" ixy="-0.008" ixz="0.005" iyy="0.023" iyz="0.001" izz="0.028"/>
    </inertial>
    <collision>
      <origin rpy="0 0 0" xyz="-0.06975 0 0"/>
      <geometry>
        <box size="0.1395 0.05 0.05"/>
      </geometry>
    </collision>
  </link>
  <!-- Upper Leg Left-->
  <link name="upper_leg_left">
    <visual>
      <origin rpy="0 0 3.141592653589793" xyz="0 0.21 0"/>
      <geometry>
        <mesh filename="package://march_description/urdf/stl-files/UpperLeftLeg.stl" scale="1 1 1"/>
      </geometry>
      <material name="blue"/>
    </visual>
    <inertial>
      <origin rpy="0 0 0" xyz="0.000709 -0.005254000000000009 -0.19205"/>
      <mass value="4.995"/>
      <inertia ixx="0.127" ixy="-0.0001291" ixz="-0.0002056" iyy="0.122" iyz="-0.016" izz="0.015"/>
    </inertial>
    <collision>
      <origin rpy="0 0 0" xyz="0 0 -0.1925"/>
      <geometry>
        <box size="0.05 0.05 0.385"/>
      </geometry>
    </collision>
  </link>
  <!-- Lower Leg Left -->
    <link name="lower_leg_left">
        <visual>
            <origin xyz="0 0 ${-lower_leg_height/2}" rpy="0 0 0"/>
            <geometry>
                <box size="${lower_leg_width_x} ${width} ${lower_leg_height}"/>
            </geometry>
        </visual>
        <inertial>
            <origin xyz="0 0 ${-lower_leg_height/2}" rpy="0 0 0"/>
            <mass value="${lower_leg_mass}"/>
            <inertia
                    ixx="${lower_leg_mass / 12.0 * (lower_leg_width_x*lower_leg_width_y + lower_leg_height*lower_leg_height)}" ixy="0.0" ixz="0.0"
                    iyy="${lower_leg_mass / 12.0 * (lower_leg_height*lower_leg_height + lower_leg_width_x*lower_leg_width_y)}" iyz="0.0"
                    izz="${lower_leg_mass / 12.0 * (lower_leg_width_x*lower_leg_width_y + lower_leg_width_x*lower_leg_width_y)}"/>
        </inertial>
        <collision>
            <origin xyz="0 0 ${-lower_leg_height/2}" rpy="0 0 0"/>
            <geometry>
                <box size="${lower_leg_width_x} ${lower_leg_width_y} ${lower_leg_height}"/>
            </geometry>
        </collision>
    </link>

  <!-- support -->
  <link name="left_support">
        <visual>
            <origin xyz="0 ${lower_leg_width_y + 0.03} -0.05" rpy="1.57 0 1.57"/>
            <geometry>
                <mesh filename="package://march_description/urdf/stl-files/support.stl" scale="0.01 0.01 0.01"/>
            </geometry>
            <material name="blue"/>
        </visual>
        <inertial> 
            <origin xyz="0.03 ${lower_leg_width_y + 0.03 -0.07} -0.05" rpy="0 0 0"/>
            <mass value="${support_mass}"/>
            <inertia
                    ixx="0.0122162" ixy="-0.0016191" ixz="0.000805"
                    iyy="0.036601" iyz="-0.00158"
                    izz="0.0184"/>
        </inertial>
        <collision>
            <origin xyz="0 ${-lower_leg_width_y/2 - 0.055} -0.05" rpy="0 0 0"/>
            <geometry>
                <box size="0.17 0.15 0.10"/>
            </geometry>
        </collision>
    </link>
  <!-- Ankle plate Left -->
  <link name="ankle_plate_left">
    <visual>
      <origin rpy="0 0 3.141592653589793" xyz="0                      0.13999999999999999                      1.0395"/>
      <geometry>
        <mesh filename="package://march_description/urdf/stl-files/LeftFoot.stl" scale="1 1 1.35"/>
      </geometry>
      <material name="blue"/>
    </visual>
    <collision>
      <origin rpy="0 0 0" xyz="0 0 -0.06"/>
      <geometry>
        <box size="0.05 0.05 0.12"/>
      </geometry>
    </collision>
  </link>
  <gazebo reference="ankle_plate_left">
    <sensor name="ankle_plate_left_contact" type="contact">
      <plugin filename="libcontact.so" name="contact_plugin"/>
      <contact>
        <collision>ankle_plate_left_fixed_joint_lump__foot_left_collision_1</collision>
      </contact>
      <update_rate>30</update_rate>
      <always_on>true</always_on>
    </sensor>
  </gazebo>
  <!-- Foot Left -->
  <link name="foot_left">
    <inertial>
      <origin rpy="0 0 0" xyz="-0.028926 -0.015916000000000013 0.10021199999999997"/>
      <mass value="1.821"/>
      <inertia ixx="0.021" ixy="0.002" ixz="0.02" iyy="0.027" iyz="-0.004" izz="0.01"/>
    </inertial>
    <collision>
      <origin rpy="0 0 0" xyz="-0.0625 0 0"/>
      <geometry>
        <box size="0.243 0.05 0.05"/>
      </geometry>
    </collision>
  </link>
  <link name="pressure_sole_left">
    <collision>
      <origin rpy="0 0 0" xyz="-0.0625 0 0"/>
      <geometry>
        <box size="0.243 0.05 0.001"/>
      </geometry>
    </collision>
  </link>
  <gazebo reference="pressure_sole_left">
    <sensor name="left_pressure_sole" type="contact">
      <always_on>true</always_on>
      <contact>
        <collision>ankle_plate_left_fixed_joint_lump__pressure_sole_left_collision_2</collision>
      </contact>
      <plugin filename="libgazebo_ros_bumper.so" name="left_foot_plugin">
        <bumperTopicName>march/sensor/left_pressure_sole</bumperTopicName>
        <frameName>world</frameName>
      </plugin>
    </sensor>
  </gazebo>
  <gazebo reference="foot_left">
    <mu1>1</mu1>
    <mu2>1</mu2>
    <minDepth>0.0005</minDepth>
    <fdir1>1 0 0</fdir1>
  </gazebo>
  <!-- Right Moving Hip-->
  <link name="hip_aa_frame_right_side">
    <visual>
      <origin rpy="0 0 3.141592653589793" xyz="-0.1395 -0.08 0"/>
      <geometry>
        <mesh filename="package://march_description/urdf/stl-files/RightHAA.stl" scale="1 1 1"/>
      </geometry>
      <material name="blue"/>
    </visual>
    <collision>
      <origin rpy="0 0 0" xyz="0 0.085 0"/>
      <geometry>
        <box size="0.05 0.17 0.05"/>
      </geometry>
    </collision>
  </link>
  <link name="hip_aa_frame_right_front">
    <inertial>
      <origin rpy="0 0 0" xyz="-0.03140600000000002 -0.05224200000000001 0.029507"/>
      <mass value="2.982"/>
      <inertia ixx="0.013" ixy="0.008" ixz="0.005" iyy="0.023" iyz="-0.001" izz="0.028"/>
    </inertial>
    <collision>
      <origin rpy="0 0 0" xyz="-0.06975 0 0"/>
      <geometry>
        <box size="0.1395 0.05 0.05"/>
      </geometry>
    </collision>
  </link>
  <!-- Upper Leg Right-->
  <link name="upper_leg_right">
    <visual>
      <origin rpy="0 0 3.141592653589793" xyz="0 -0.21 0"/>
      <geometry>
        <mesh filename="package://march_description/urdf/stl-files/UpperRightLeg.stl" scale="1 1 1"/>
      </geometry>
      <material name="blue"/>
    </visual>
    <inertial>
      <origin rpy="0 0 0" xyz="0.000709 0.005254000000000009 -0.19205"/>
      <mass value="4.995"/>
      <inertia ixx="0.127" ixy="0.0001291" ixz="-0.0002056" iyy="0.122" iyz="0.016" izz="0.015"/>
    </inertial>
    <collision>
      <origin rpy="0 0 0" xyz="0 0 -0.1925"/>
      <geometry>
        <box size="0.05 0.05 0.385"/>
      </geometry>
    </collision>
  </link>
  <!-- Lower Leg Right -->
    <link name="lower_leg_right">
        <visual>
            <origin xyz="0 0 ${-lower_leg_height/2}" rpy="0 0 0"/>
            <geometry>
                <box size="${lower_leg_width_x} ${lower_leg_width_y} ${lower_leg_height}"/>
            </geometry>
        </visual>
        <inertial>
            <origin xyz="0 0 ${-lower_leg_height/2}" rpy="0 0 0"/>
            <mass value="${lower_leg_mass}"/>
            <inertia
                    ixx="${lower_leg_mass / 12.0 * (lower_leg_width_x*lower_leg_width_y + lower_leg_height*lower_leg_height)}" ixy="0.0" ixz="0.0"
                    iyy="${lower_leg_mass / 12.0 * (lower_leg_height*lower_leg_height + lower_leg_width_x*lower_leg_width_y)}" iyz="0.0"
                    izz="${lower_leg_mass / 12.0 * (lower_leg_width_x*lower_leg_width_y + lower_leg_width_x*lower_leg_width_y)}"/>
        </inertial>
        <collision>
            <origin xyz="0 0 ${-lower_leg_height/2}" rpy="0 0 0"/>
            <geometry>
                <box size="${lower_leg_width_x} ${lower_leg_width_y} ${lower_leg_height}"/>
            </geometry>
        </collision>
    </link>

        <!-- support -->

    <link name="right_support">
        <visual>
            <origin xyz="0 ${-lower_leg_width_y/2 - 0.055} -0.05" rpy="1.57 0 -1.57"/>
            <geometry>
                <mesh filename="package://march_description/urdf/stl-files/support.stl" scale="0.01 0.01 0.01"/>
            </geometry>
            <material name="blue"/>
        </visual>
        <inertial>
            <origin xyz="0.03 ${-lower_leg_width_y/2 - 0.055 -0.07} -0.05" rpy="0 0 0"/>
            <mass value="${support_mass}"/>
            <inertia
                    ixx="0.0122162" ixy="-0.0016191" ixz="0.000805"
                    iyy="0.036601" iyz="-0.00158"
                    izz="0.0184"/>
        </inertial>
        <collision>
            <origin xyz="0 ${-lower_leg_width_y/2 - 0.055} -0.05" rpy="0 0 0"/>
            <geometry>
                <box size="0.17 0.15 0.10"/>
            </geometry>
        </collision>
    </link>
  <!-- Ankle Plate Right -->
  <link name="ankle_plate_right">
    <visual>
      <origin rpy="0 0 3.141592653589793" xyz="0                     -0.13999999999999999                     1.0395"/>
      
            /&gt;
            
      <geometry>
        <mesh filename="package://march_description/urdf/stl-files/RightFoot.stl" scale="1 1 1.35"/>
      </geometry>
      <material name="blue"/>
    </visual>
    <collision>
      <origin rpy="0 0 0" xyz="0 0 -0.06"/>
      <geometry>
        <box size="0.05 0.05 0.12"/>
      </geometry>
    </collision>
  </link>
  <gazebo reference="ankle_plate_right">
    <sensor name="ankle_plate_right_contact" type="contact">
      <plugin filename="libcontact.so" name="contact_plugin"/>
      <contact>
        <collision>ankle_plate_right_fixed_joint_lump__foot_right_collision_1</collision>
      </contact>
      <update_rate>30</update_rate>
      <always_on>true</always_on>
    </sensor>
  </gazebo>
  <!-- Foot Right -->
  <link name="foot_right">
    <inertial>
      <origin rpy="0 0 0" xyz="-0.028926 0.015916000000000013 0.10021199999999997"/>
      <mass value="1.821"/>
      <inertia ixx="0.021" ixy="-0.002" ixz="0.02" iyy="0.027" iyz="0.004" izz="0.01"/>
    </inertial>
    <collision>
      <origin rpy="0 0 0" xyz="-0.0625 0 0"/>
      <geometry>
        <box size="0.243 0.05 0.05"/>
      </geometry>
    </collision>
  </link>
  <gazebo reference="foot_right">
    <mu1>1</mu1>
    <mu2>1</mu2>
    <minDepth>0.0005</minDepth>
    <fdir1>1 0 0</fdir1>
  </gazebo>
  <link name="pressure_sole_right">
    <collision>
      <origin rpy="0 0 0" xyz="-0.0625 0 0"/>
      <geometry>
        <box size="0.243 0.05 0.001"/>
      </geometry>
    </collision>
  </link>
  <gazebo reference="pressure_sole_right">
    <sensor name="right_pressure_sole" type="contact">
      <always_on>true</always_on>
      <contact>
        <collision>ankle_plate_right_fixed_joint_lump__pressure_sole_right_collision_2</collision>
      </contact>
      <plugin filename="libgazebo_ros_bumper.so" name="right_foot_plugin">
        <bumperTopicName>march/sensor/right_pressure_sole</bumperTopicName>
        <frameName>world</frameName>
      </plugin>
    </sensor>
  </gazebo>
  <!-- Joints -->
  <joint name="imu_joint" type="fixed">
    <parent link="world"/>
    <child link="imu_link"/>
  </joint>
  <joint name="hip" type="fixed">
    <parent link="imu_link"/>
    <child link="hip_base"/>
    <origin rpy="0 0 0" xyz="0 0 1.215"/>
  </joint>
  <joint name="left_hip_aa" type="revolute">
    <parent link="hip_base"/>
    <child link="hip_aa_frame_left_side"/>
    <origin rpy="0 0 0" xyz="0 -0.08 0"/>
    <axis xyz="-1 0 0"/>
    <limit effort="22932.0" lower="-0.32366994633113677" upper="0.2853204265467293" velocity="1.0"/>
    <safety_controller k_position="4.0" k_velocity="20000.0" soft_lower_limit="-0.26258342251133526" soft_upper_limit="0.22423390272692775"/>
  </joint>
  <joint name="left_hip_angle" type="fixed">
    <parent link="hip_aa_frame_left_side"/>
    <child link="hip_aa_frame_left_front"/>
    <origin rpy="0 0 0" xyz="0 -0.17 0"/>
  </joint>
  <joint name="left_hip_fe" type="revolute">
    <parent link="hip_aa_frame_left_front"/>
    <child link="upper_leg_left"/>
    <origin rpy="0 0 0" xyz="-0.1395 0.04 0"/>
    <axis xyz="0 1 0"/>
    <limit effort="18000.0" lower="-0.3672925248393725" upper="1.7273582408875707" velocity="2.0"/>
    <safety_controller k_position="14.88" k_velocity="20000.0" soft_lower_limit="-0.3149326472795426" soft_upper_limit="1.6749983633277408"/>
  </joint>
  <joint name="left_knee" type="revolute">
    <parent link="upper_leg_left"/>
    <child link="lower_leg_left"/>
    <origin rpy="0 0 0" xyz="0 0 -0.385"/>
    <axis xyz="0 -1 0"/>
    <limit effort="18000.0" lower="-0.08748484180855756" upper="1.9621531752496792" velocity="2.5"/>
    <safety_controller k_position="14.88" k_velocity="20000.0" soft_lower_limit="-0.026398317988756026" soft_upper_limit="1.9097932976898493"/>
  </joint>
  <joint name="left_fixing" type="fixed">
        <parent link="lower_leg_left"/>
        <child link="left_support"/>
        <origin xyz="0 ${lower_leg_width_y/2} ${-lower_leg_height/2}" rpy="0 0 0"/>
    </joint>
  <joint name="left_ankle" type="revolute">
    <parent link="lower_leg_left"/>
    <child link="ankle_plate_left"/>
    <origin rpy="0 0 0" xyz="0 0.07 -0.385"/>
    <axis xyz="0 1 0"/>
    <limit effort="22932.0" lower="-0.45909168761713093" upper="0.27721909056797683" velocity="1.0"/>
    <safety_controller k_position="5.0" k_velocity="20000.0" soft_lower_limit="-0.406731810057301" soft_upper_limit="0.18995262796826035"/>
  </joint>
  <joint name="left_foot_angle" type="fixed">
    <parent link="ankle_plate_left"/>
    <child link="foot_left"/>
    <origin rpy="0 0 0" xyz="0 0 -0.12"/>
  </joint>
  <joint name="left_pressure_sole_joint" type="fixed">
    <parent link="foot_left"/>
    <child link="pressure_sole_left"/>
    <origin rpy="0 0 0" xyz="0 0 -0.025"/>
  </joint>
  <joint name="right_pressure_sole_joint" type="fixed">
    <parent link="foot_right"/>
    <child link="pressure_sole_right"/>
    <origin rpy="0 0 0" xyz="0 0 -0.025"/>
  </joint>
  <joint name="right_hip_aa" type="revolute">
    <parent link="hip_base"/>
    <child link="hip_aa_frame_right_side"/>
    <origin rpy="0 0 0" xyz="0 0.08 0"/>
    <axis xyz="1 0 0"/>
    <limit effort="22932.0" lower="-0.31600004230444206" upper="0.2791845033951867" velocity="1.0"/>
    <safety_controller k_position="4.0" k_velocity="20000.0" soft_lower_limit="-0.2549135184846405" soft_upper_limit="0.21809797957538515"/>
  </joint>
  <joint name="right_hip_angle" type="fixed">
    <parent link="hip_aa_frame_right_side"/>
    <child link="hip_aa_frame_right_front"/>
    <origin rpy="0 0 0" xyz="0 0.17 0"/>
  </joint>
  <joint name="right_hip_fe" type="revolute">
    <parent link="hip_aa_frame_right_front"/>
    <child link="upper_leg_right"/>
    <origin rpy="0 0 0" xyz="-0.1395 -0.04 0"/>
    <axis xyz="0 1 0"/>
    <limit effort="18000.0" lower="-0.3531511394374164" upper="1.7362745042553351" velocity="2.0"/>
    <safety_controller k_position="14.88" k_velocity="20000.0" soft_lower_limit="-0.3007912618775865" soft_upper_limit="1.6839146266955052"/>
  </joint>
  <joint name="right_knee" type="revolute">
    <parent link="upper_leg_right"/>
    <child link="lower_leg_right"/>
    <origin rpy="0 0 0" xyz="0 0 -0.385"/>
    <axis xyz="0 -1 0"/>
    <limit effort="18000.0" lower="-0.0854235551308358" upper="2.012534856492726" velocity="2.5"/>
    <safety_controller k_position="14.88" k_velocity="20000.0" soft_lower_limit="-0.024337031311034263" soft_upper_limit="1.9601749789328962"/>
  </joint>
  <joint name="right_fixing" type="fixed">
        <parent link="lower_leg_right"/>
        <child link="right_support"/>
        <origin xyz="0 ${-lower_leg_width_y/2} ${-lower_leg_height/2}" rpy="0 0 0"/>
    </joint>
  <joint name="right_ankle" type="revolute">
    <parent link="lower_leg_right"/>
    <child link="ankle_plate_right"/>
    <origin rpy="0 0 0" xyz="0 -0.07 -0.385"/>
    <axis xyz="0 1 0"/>
    <limit effort="22932.0" lower="-0.4049709280018093" upper="0.24850488763747386" velocity="1.0"/>
    <safety_controller k_position="5.0" k_velocity="20000.0" soft_lower_limit="-0.3526110504419794" soft_upper_limit="0.16123842503775737"/>
  </joint>
  <joint name="right_foot_angle" type="fixed">
    <parent link="ankle_plate_right"/>
    <child link="foot_right"/>
    <origin rpy="0 0 0" xyz="0 0 -0.12"/>
  </joint>
  <material name="camera_aluminum">
    <color rgba="0.5 0.5 0.5 1"/>
  </material>
  <!-- camera body, with origin at bottom screw mount -->
  <joint name="camera_joint" type="fixed">
    <origin rpy="1.5707963267948966 0.7853981633974483 3.141592653589793" xyz="-0.17 0.195 0.215"/>
    <parent link="hip_base"/>
    <child link="camera_bottom_screw_frame"/>
  </joint>
  <link name="camera_bottom_screw_frame"/>
  <joint name="camera_link_joint" type="fixed">
    <origin rpy="0 0 0" xyz="0 0.0175 0.0125"/>
    <parent link="camera_bottom_screw_frame"/>
    <child link="camera_link"/>
  </joint>
  <link name="camera_link">
    <visual>
      <origin rpy="1.5707963267948966 0 1.5707963267948966" xyz="0.0149 -0.0175 0"/>
      <geometry>
        <!-- <box size="${d435_cam_width} ${d435_cam_height} ${d435_cam_depth}"/> -->
        <mesh filename="package://march_description/urdf/camera/_d435.dae"/>
      </geometry>
      <material name="camera_aluminum"/>
    </visual>
    <collision>
      <origin rpy="0 0 0" xyz="0 -0.0175 0"/>
      <geometry>
        <box size="0.02505 0.09 0.025"/>
      </geometry>
    </collision>
    <inertial>
      <!-- The following are not reliable values, and should not be used for modeling -->
      <mass value="0.564"/>
      <origin xyz="0 0 0"/>
      <inertia ixx="0.003881243" ixy="0.0" ixz="0.0" iyy="0.000498940" iyz="0.0" izz="0.003879257"/>
    </inertial>
  </link>
  <!-- camera depth joints and links -->
  <joint name="camera_depth_joint" type="fixed">
    <origin rpy="0 0 0" xyz="0 0 0"/>
    <parent link="camera_link"/>
    <child link="camera_depth_frame"/>
  </joint>
  <link name="camera_depth_frame"/>
  <joint name="camera_depth_optical_joint" type="fixed">
    <origin rpy="-1.5707963267948966 0 -1.5707963267948966" xyz="0 0 0"/>
    <parent link="camera_depth_frame"/>
    <child link="camera_depth_optical_frame"/>
  </joint>
  <link name="camera_depth_optical_frame"/>
  <!-- camera left IR joints and links -->
  <joint name="camera_left_ir_joint" type="fixed">
    <origin rpy="0 0 0" xyz="0 0.0 0"/>
    <parent link="camera_depth_frame"/>
    <child link="camera_left_ir_frame"/>
  </joint>
  <link name="camera_left_ir_frame"/>
  <joint name="camera_left_ir_optical_joint" type="fixed">
    <origin rpy="-1.5707963267948966 0 -1.5707963267948966" xyz="0 0 0"/>
    <parent link="camera_left_ir_frame"/>
    <child link="camera_left_ir_optical_frame"/>
  </joint>
  <link name="camera_left_ir_optical_frame"/>
  <!-- camera right IR joints and links -->
  <joint name="camera_right_ir_joint" type="fixed">
    <origin rpy="0 0 0" xyz="0 -0.05 0"/>
    <parent link="camera_depth_frame"/>
    <child link="camera_right_ir_frame"/>
  </joint>
  <link name="camera_right_ir_frame"/>
  <joint name="camera_right_ir_optical_joint" type="fixed">
    <origin rpy="-1.5707963267948966 0 -1.5707963267948966" xyz="0 0 0"/>
    <parent link="camera_right_ir_frame"/>
    <child link="camera_right_ir_optical_frame"/>
  </joint>
  <link name="camera_right_ir_optical_frame"/>
  <!-- camera color joints and links -->
  <joint name="camera_color_joint" type="fixed">
    <origin rpy="0 0 0" xyz="0 0.015 0"/>
    <parent link="camera_depth_frame"/>
    <child link="camera_color_frame"/>
  </joint>
  <link name="camera_color_frame"/>
  <joint name="camera_color_optical_joint" type="fixed">
    <origin rpy="-1.5707963267948966 0 -1.5707963267948966" xyz="0 0 0"/>
    <parent link="camera_color_frame"/>
    <child link="camera_color_optical_frame"/>
  </joint>
  <link name="camera_color_optical_frame"/>
  <!-- ROS Control plugin for Gazebo -->
  <transmission name="left_hip_aa">
    <type>transmission_interface/SimpleTransmission</type>
    <joint name="left_hip_aa">
      <hardwareInterface>hardware_interface/EffortJointInterface</hardwareInterface>
    </joint>
    <actuator name="left_hip_aa_motor">
      <mechanicalReduction>200</mechanicalReduction>
    </actuator>
  </transmission>
  <transmission name="left_hip_fe">
    <type>transmission_interface/SimpleTransmission</type>
    <joint name="left_hip_fe">
      <hardwareInterface>hardware_interface/EffortJointInterface</hardwareInterface>
    </joint>
    <actuator name="left_hip_fe_motor">
      <mechanicalReduction>101</mechanicalReduction>
    </actuator>
  </transmission>
  <transmission name="left_knee">
    <type>transmission_interface/SimpleTransmission</type>
    <joint name="left_knee">
      <hardwareInterface>hardware_interface/EffortJointInterface</hardwareInterface>
    </joint>
    <actuator name="left_knee_motor">
      <mechanicalReduction>101</mechanicalReduction>
    </actuator>
  </transmission>
  <transmission name="left_ankle">
    <type>transmission_interface/SimpleTransmission</type>
    <joint name="left_ankle">
      <hardwareInterface>hardware_interface/EffortJointInterface</hardwareInterface>
    </joint>
    <actuator name="left_ankle_motor">
      <mechanicalReduction>200</mechanicalReduction>
    </actuator>
  </transmission>
  <transmission name="right_hip_aa">
    <type>transmission_interface/SimpleTransmission</type>
    <joint name="right_hip_aa">
      <hardwareInterface>hardware_interface/EffortJointInterface</hardwareInterface>
    </joint>
    <actuator name="right_hip_aa_motor">
      <mechanicalReduction>200</mechanicalReduction>
    </actuator>
  </transmission>
  <transmission name="right_hip_fe">
    <type>transmission_interface/SimpleTransmission</type>
    <joint name="right_hip_fe">
      <hardwareInterface>hardware_interface/EffortJointInterface</hardwareInterface>
    </joint>
    <actuator name="right_hip_fe_motor">
      <mechanicalReduction>101</mechanicalReduction>
    </actuator>
  </transmission>
  <transmission name="right_knee">
    <type>transmission_interface/SimpleTransmission</type>
    <joint name="right_knee">
      <hardwareInterface>hardware_interface/EffortJointInterface</hardwareInterface>
    </joint>
    <actuator name="right_knee_motor">
      <mechanicalReduction>101</mechanicalReduction>
    </actuator>
  </transmission>
  <transmission name="right_ankle">
    <type>transmission_interface/SimpleTransmission</type>
    <joint name="right_ankle">
      <hardwareInterface>hardware_interface/EffortJointInterface</hardwareInterface>
    </joint>
    <actuator name="right_ankle_motor">
      <mechanicalReduction>200</mechanicalReduction>
    </actuator>
  </transmission>
</robot>
