<?xml version="1.0" ?>
<!-- =================================================================================== -->
<!-- |    This document was autogenerated by xacro from urdf/march3.xacro              | -->
<!-- |    EDITING THIS FILE BY HAND IS NOT RECOMMENDED                                 | -->
<!-- =================================================================================== -->
<!-- Revolute-Revolute Manipulator -->
<robot name="march">
  <!-- Square dimensions (widthxwidth) of beams -->
  <!-- rad/s -->
  <!-- Space btw top of beam and the each joint -->
  <gazebo>
    <plugin filename="libgazebo_ros_control.so" name="gazebo_ros_control">
      <robotNamespace>/march</robotNamespace>
      <robotSimType>gazebo_ros_control/DefaultRobotHWSim</robotSimType>
    </plugin>
  </gazebo>
  <plugin filename="libgazebo_ros_control.so" name="gazebo_ros_control">
    <robotNamespace>/march</robotNamespace>
  </plugin>
  <!-- Used for fixing robot to Gazebo 'base_link' -->
  <link name="world"/>
  <joint name="hip" type="fixed">
    <parent link="world"/>
    <child link="hip_bone"/>
    <origin rpy="0 0 0" xyz="0 0 1.08"/>
  </joint>
  <joint name="left_hip" type="revolute">
    <parent link="hip_bone"/>
    <child link="upper_leg_left"/>
    <origin rpy="0 0 0" xyz="0 -0.165 0"/>
    <axis xyz="0 1 0"/>
    <limit effort="1000.0" lower="-0.2617993877991494" upper="1.8325957145940461" velocity="1000.0"/>
  </joint>
  <joint name="left_knee" type="revolute">
    <parent link="upper_leg_left"/>
    <child link="lower_leg_left"/>
    <origin rpy="0 0 0" xyz="0 0 -0.39"/>
    <axis xyz="0 -1 0"/>
    <limit effort="1000.0" lower="-0.2617993877991494" upper="1.8325957145940461" velocity="1000.0"/>
  </joint>
  <joint name="left_ankle" type="revolute">
    <parent link="lower_leg_left"/>
    <child link="foot_left"/>
    <origin rpy="0 0 0" xyz="0 0 -0.39"/>
    <axis xyz="0 1 0"/>
    <limit effort="1000.0" lower="-0.2617993877991494" upper="0.3490658503988659" velocity="1000.0"/>
  </joint>
  <joint name="right_hip" type="revolute">
    <parent link="hip_bone"/>
    <child link="upper_leg_right"/>
    <origin rpy="0 0 0" xyz="0 0.165 0"/>
    <axis xyz="0 1 0"/>
    <limit effort="1000.0" lower="-0.2617993877991494" upper="1.8325957145940461" velocity="1000.0"/>
  </joint>
  <joint name="right_knee" type="revolute">
    <parent link="upper_leg_right"/>
    <child link="lower_leg_right"/>
    <origin rpy="0 0 0" xyz="0 0 -0.39"/>
    <axis xyz="0 -1 0"/>
    <limit effort="1000.0" lower="-0.2617993877991494" upper="1.8325957145940461" velocity="1000.0"/>
  </joint>
  <joint name="right_ankle" type="revolute">
    <parent link="lower_leg_right"/>
    <child link="foot_right"/>
    <origin rpy="0 0 0" xyz="0 0 -0.39"/>
    <axis xyz="0 1 0"/>
    <limit effort="1000.0" lower="-0.2617993877991494" upper="0.3490658503988659" velocity="1000.0"/>
  </joint>
  <!-- give colors to some links in gazebo -->
  <gazebo reference="hip_bone">
    <material>Gazebo/Blue</material>
  </gazebo>
  <gazebo reference="foot_left">
    <material>Gazebo/Blue</material>
  </gazebo>
  <gazebo reference="foot_right">
    <material>Gazebo/Blue</material>
  </gazebo>
  <!-- Hip-->
  <link name="hip_bone">
    <visual>
      <origin rpy="0 0 0" xyz="0 0 0"/>
      <geometry>
        <box size="0.05 0.33 0.05"/>
      </geometry>
    </visual>
    <inertial>
      <origin rpy="0 0 0" xyz="0 0 0"/>
      <mass value="1"/>
      <inertia ixx="0.012883333333333333" ixy="0.0" ixz="0.0" iyy="0.012883333333333333" iyz="0.0" izz="0.00041666666666666675"/>
    </inertial>
  </link>
  <!-- Upper Leg Left-->
  <link name="upper_leg_left">
    <visual>
      <origin rpy="0 0 0" xyz="0 0 -0.195"/>
      <geometry>
        <box size="0.05 0.05 0.39"/>
      </geometry>
    </visual>
    <inertial>
      <origin rpy="0 0 0" xyz="0 0 -0.195"/>
      <mass value="1.08"/>
      <inertia ixx="0.012883333333333333" ixy="0.0" ixz="0.0" iyy="0.012883333333333333" iyz="0.0" izz="0.00041666666666666675"/>
    </inertial>
  </link>
  <!-- Lower Leg Left -->
  <link name="lower_leg_left">
    <visual>
      <origin rpy="0 0 0" xyz="0 0 -0.195"/>
      <geometry>
        <box size="0.05 0.05 0.39"/>
      </geometry>
    </visual>
    <inertial>
      <origin rpy="0 0 0" xyz="0 0 -0.195"/>
      <mass value="1.133"/>
      <inertia ixx="0.012883333333333333" ixy="0.0" ixz="0.0" iyy="0.012883333333333333" iyz="0.0" izz="0.00041666666666666675"/>
    </inertial>
  </link>
  <!-- Foot Left -->
  <link name="foot_left">
    <visual>
      <origin rpy="0 0 0" xyz="-0.07 0 0"/>
      <geometry>
        <box size="0.14 0.05 0.05"/>
      </geometry>
    </visual>
    <inertial>
      <origin rpy="0 0 0" xyz="-0.07 0 0"/>
      <mass value="0.393"/>
      <inertia ixx="0.012883333333333333" ixy="0.0" ixz="0.0" iyy="0.012883333333333333" iyz="0.0" izz="0.00041666666666666675"/>
    </inertial>
    <collision>
      <geometry>
        <box size="0.14 0.05 0.05"/>
      </geometry>
    </collision>
  </link>
  <!-- Upper Leg Right-->
  <link name="upper_leg_right">
    <visual>
      <origin rpy="0 0 0" xyz="0 0 -0.195"/>
      <geometry>
        <box size="0.05 0.05 0.39"/>
      </geometry>
    </visual>
    <inertial>
      <origin rpy="0 0 0" xyz="0 0 -0.195"/>
      <mass value="1.08"/>
      <inertia ixx="0.012883333333333333" ixy="0.0" ixz="0.0" iyy="0.012883333333333333" iyz="0.0" izz="0.00041666666666666675"/>
    </inertial>
  </link>
  <!-- Lower Leg Right -->
  <link name="lower_leg_right">
    <visual>
      <origin rpy="0 0 0" xyz="0 0 -0.195"/>
      <geometry>
        <box size="0.05 0.05 0.39"/>
      </geometry>
    </visual>
    <inertial>
      <origin rpy="0 0 0" xyz="0 0 -0.195"/>
      <mass value="1.133"/>
      <inertia ixx="0.012883333333333333" ixy="0.0" ixz="0.0" iyy="0.012883333333333333" iyz="0.0" izz="0.00041666666666666675"/>
    </inertial>
  </link>
  <!-- Foot Right -->
  <link name="foot_right">
    <visual>
      <origin rpy="0 0 0" xyz="-0.07 0 0"/>
      <geometry>
        <box size="0.14 0.05 0.05"/>
      </geometry>
    </visual>
    <inertial>
      <origin rpy="0 0 0" xyz="-0.07 0 0"/>
      <mass value="1"/>
      <inertia ixx="0.012883333333333333" ixy="0.0" ixz="0.0" iyy="0.012883333333333333" iyz="0.0" izz="0.00041666666666666675"/>
    </inertial>
    <collision>
      <geometry>
        <box size="0.14 0.05 0.05"/>
      </geometry>
    </collision>
  </link>
  <!-- ROS Control plugin for Gazebo -->
  <transmission name="left_hip">
    <type>transmission_interface/SimpleTransmission</type>
    <joint name="left_hip">
      <hardwareInterface>hardware_interface/EffortJointInterface</hardwareInterface>
    </joint>
    <actuator name="left_hip_motor">
      <hardwareInterface>hardware_interface/EffortJointInterface</hardwareInterface>
      <mechanicalReduction>1</mechanicalReduction>
    </actuator>
  </transmission>
  <transmission name="left_knee">
    <type>transmission_interface/SimpleTransmission</type>
    <joint name="left_knee">
      <hardwareInterface>hardware_interface/EffortJointInterface</hardwareInterface>
    </joint>
    <actuator name="left_knee_motor">
      <hardwareInterface>hardware_interface/EffortJointInterface</hardwareInterface>
      <mechanicalReduction>1</mechanicalReduction>
    </actuator>
  </transmission>
  <transmission name="left_ankle">
    <type>transmission_interface/SimpleTransmission</type>
    <joint name="left_ankle">
      <hardwareInterface>hardware_interface/EffortJointInterface</hardwareInterface>
    </joint>
    <actuator name="left_ankle_motor">
      <hardwareInterface>hardware_interface/EffortJointInterface</hardwareInterface>
      <mechanicalReduction>1</mechanicalReduction>
    </actuator>
  </transmission>
  <transmission name="right_hip">
    <type>transmission_interface/SimpleTransmission</type>
    <joint name="right_hip">
      <hardwareInterface>hardware_interface/EffortJointInterface</hardwareInterface>
    </joint>
    <actuator name="right_hip_motor">
      <hardwareInterface>hardware_interface/EffortJointInterface</hardwareInterface>
      <mechanicalReduction>1</mechanicalReduction>
    </actuator>
  </transmission>
  <transmission name="right_knee">
    <type>transmission_interface/SimpleTransmission</type>
    <joint name="right_knee">
      <hardwareInterface>hardware_interface/EffortJointInterface</hardwareInterface>
    </joint>
    <actuator name="right_knee_motor">
      <hardwareInterface>hardware_interface/EffortJointInterface</hardwareInterface>
      <mechanicalReduction>1</mechanicalReduction>
    </actuator>
  </transmission>
  <transmission name="right_ankle">
    <type>transmission_interface/SimpleTransmission</type>
    <joint name="right_ankle">
      <hardwareInterface>hardware_interface/EffortJointInterface</hardwareInterface>
    </joint>
    <actuator name="right_ankle_motor">
      <hardwareInterface>hardware_interface/EffortJointInterface</hardwareInterface>
      <mechanicalReduction>1</mechanicalReduction>
    </actuator>
  </transmission>
</robot>
